Workbook

Sheet Таб1
A1: Параметры уходящих из печи технологических газов и воздуха | B1: Единица | C1: Значение
A2: Тип энерготехнологического агрегата | C2: Другие ЭТА
A3: Источник технологического уноса
A4: Количество газов над ванной печи | B4: нм3/ч | C4: 34000
A5: Температура уходящих из печи технологических газов | B5: оC | C5: 1250
A6: Температура уходящих из КУ технологических газов | B6: оC | C6: 400
A7: Средняя крупность пыли | B7: мкр | C7: =IF(C2=Пр7!A14,"Введите данные в следующую ячейку",SUMIF(Пр7!A:A,Таб1!$C$2,Пр7!X:X)) -> Введите данные в следующую ячейку
A8: Средняя крупность пыли (ручной ввод) | B8: мкр | C8: 30
A9: Давление уходящих из печи технологических газов | B9: кгс/м2 | C9: 9999.8095
A10: Давление уходящих из КУ технологических газов | B10: кгс/м2 | C10: 9500
A11: Запыленность газов над ванной | B11: г/нм3 | C11: 35
A12: Доля подсоса воздуха в печь | B12: % | C12: 0.05
A13: Доля подсоса воздуха в КУ | B13: % | C13: 0.1
A14: Среднегодовая температура воздуха | B14: оC | C14: 16.7
A15: SO2 на выходе из печи | B15: % | C15: 0.2342
A16: SO3 на выходе из печи | B16: % | C16: 0
A17: H2O на выходе из печи | B17: % | C17: 0.3476
A18: O2 на выходе из печи | B18: % | C18: 0.05
A19: N2 на выходе из печи | B19: % | C19: 0.2546
... A27: Доля пара в пароводяной смеси | B27: % | C27: 0.025

Sheet Таб2
A1: Конструктивные характеристики КУ | B1: Единица | C1: Зона 1 | D1: Зона 2 | E1: Зона 3 | F1: Зона 4 | G1: Зона 5 | H1: Зона 6 | I1: Зона 7 | J1: Зона 8 | K1: Зона 9 | L1: Зона 10 | M1: Зона XX
A2: Наименование тепловой зоны | B2: - | C2: Воротник | D2: Радиационная шахта | E2: Холодная воронка 1 | F2: Конвективная шахта | G2: Переход | H2: Газоохладитель без ширмы
A3: Расположение зоны | C3: Горизонтальное | D3: Вертикальное | E3: Горизонтальное | F3: Вертикальное | G3: Горизонтальное | H3: Вертикальное
A4: Длина проходного канала по зонам | B4: м | C4: 2.5 | D4: 12.28 | E4: =(8.5+6.703)*0.5 -> 7.6015 | F4: 13.8 | G4: 1.4 | H4: =Таб2_Конструкция_КУ[[#This Row],[Зона 4]] -> 13.8
A5: Ширина проходного канала по зонам | B5: м | C5: =(8.8+4.488)*0.5 -> 6.644 | D5: 10.5 | E5: =0.5*((Таб2_Конструкция_КУ[[#This Row],[Зона 2]]-2)/2+1) -> 2.625 | F5: 4.25 | G5: =Таб2_Конструкция_КУ[[#This Row],[Зона 4]] -> 4.25 | H5: =Таб2_Конструкция_КУ[[#This Row],[Зона 4]] -> 4.25
A6: Высота вертикальной части проходного канала | B6: м | C6: =(6.918+3.525)*0.5 -> 5.2215 | D6: 7 | E6: 3.3 | F6: 2.5 | G6: 3.7 | H6: =Таб2_Конструкция_КУ[[#This Row],[Зона 4]] -> 2.5
A7: Высота конической части проходного канала | G7: =(11600-8600)/1000 -> 3
A8: Площадь стеновой поверхности нагрева | B8: м2 | C8: =2*(C5+C6)*C4 -> 59.3275 | D8: =2*(D5+D6)*D4+D5*D6-C5*C6 -> 468.60835 | E8: =2*2*(E5+E6)*E4-D5*D6-2*F5*F6 -> 85.40555 | F8: =2*(2*(F5+F6)*F4+F5*F6-G5*G6) -> 362.4 | G8: =2*(2*(G5+G6)*G4) -> 44.52 | H8: =2*(2*(H5+H6)*H4+H5*H6-G5*G6) -> 362.4
A9: Площадь ширмовой поверхности нагрева | B9: м2 | C9: 0 | D9: 0 | E9: 0 | F9: 0 | G9: =G10*G13 -> 0 | H9: =H10*H13 -> 0
A10: Площадь удельной поверхности ширм | B10: м2 | C10: 0 | D10: 0 | E10: 0 | F10: 0 | G10: 39 | H10: 39
A11: Ширина ширмы | B11: м | C11: 0 | D11: 0 | E11: 0 | F11: 0 | G11: 1.9 | H11: 1.9
A12: Толщина ширмы | B12: м | C12: 0.032 | D12: 0.032 | E12: 0.032 | F12: 0.032 | G12: 0.032 | H12: 0.032
A13: Количество ширм | B13: шт | C13: 0 | D13: 0 | E13: 0 | F13: 0 | G13: 0 | H13: 0
A14: Шаг между ширмами | B14: м | C14: =IF(C13>0,C5/C13,0) -> 0 | D14: =IF(D13>0,D5/D13,0) -> 0 | E14: =IF(E13>0,E5/E13,0) -> 0 | F14: =IF(F13>0,F5/F13,0) -> 0 | G14: =IF(G13>0,G5/G13,0) -> 0 | H14: =IF(H13>0,H5/H13,0) -> 0
A15: Толщина стенки нагрева по зонам | B15: м | C15: 0.013 | D15: 0.013 | E15: 0.013 | F15: 0.013 | G15: 0.013 | H15: 0.013
A16: Коэффициент загрязнения поверхности нагрева, средний | B16: (м2*ч*оС)/ккал | C16: 0.005 | D16: 0.005 | E16: 0.005 | F16: 0.005 | G16: 0.005 | H16: 0.005 | M16: Кузнецов Т.6-3 С.30; П.7-Б,д) С.46
A17: Толщина пылевых отложений на поверхности нагрева по зонам | B17: мм | C17: 0.8 | D17: 0.8 | E17: 0.8 | F17: 0.8 | G17: 0.8 | H17: 0.8
A18: Наружная температура поверхности нагрева по зонам | B18: оC | C18: =IF(100*Таб6!C34/Таб6!$C$34<60,60,100*Таб6!C34/Таб6!$C$34) -> 100 | D18: =IF(100*Таб6!D34/Таб6!$C$34<60,60,100*Таб6!D34/Таб6!$C$34) -> 79.752066 | E18: =IF(100*Таб6!E34/Таб6!$C$34<60,60,100*Таб6!E34/Таб6!$C$34) -> 66.900826 | F18: =IF(100*Таб6!F34/Таб6!$C$34<60,60,100*Таб6!F34/Таб6!$C$34) -> 60 | G18: =IF(100*Таб6!G34/Таб6!$C$34<60,60,100*Таб6!G34/Таб6!$C$34) -> 60 | H18: =IF(100*Таб6!H34/Таб6!$C$34<60,60,100*Таб6!H34/Таб6!$C$34) -> 60
A19: Перепад температуры технологических газов по зонам | B19: оC | C19: 80 | D19: 450 | E19: 66 | F19: 141 | G19: 11 | H19: 71
C20: =Таб1!C5-Таб2!C19 -> 1170 | D20: =Таб2_Конструкция_КУ[[#This Row],[Зона 1]]-D19 -> 720 | E20: =Таб2_Конструкция_КУ[[#This Row],[Зона 2]]-E19 -> 654 | F20: =Таб2_Конструкция_КУ[[#This Row],[Зона 3]]-F19 -> 513 | G20: =Таб2_Конструкция_КУ[[#This Row],[Зона 4]]-G19 -> 502 | H20: =Таб2_Конструкция_КУ[[#This Row],[Зона 5]]-H19 -> 431

Sheet Таб8
A1: Наименование | B1: Обозначение | C1: Единица измерения | D1: Зона 1 | E1: Зона 2 | F1: Зона 3 | G1: Зона 4 | H1: Зона 5 | I1: Зона 6 | J1: Зона 7 | K1: Зона 8 | L1: Зона 9 | M1: Зона 10 | N1: Зона XX
A2: Средняя скорость потока газов в зоне | C2: м/с | D2: =Таб6!C7*Таб6!C35/273/(3600*Таб5!C10) -> 1.5565107 | E2: =Таб6!D7*Таб6!D35/273/(3600*Таб5!D10) -> 0.61620817 | F2: =Таб6!E7*Таб6!E35/273/(3600*Таб5!E10) -> 2.329087 | G2: =Таб6!F7*Таб6!F35/273/(3600*Таб5!F10) -> 1.6882662 | H2: =Таб6!G7*Таб6!G35/273/(3600*(Таб5!G10+Таб5!H10)) -> 0.63114809 | I2: =Таб6!H7*Таб6!H35/273/(3600*Таб5!H10) -> 1.4336559 | J2: =Таб6!I7*Таб6!I35/273/(3600*Таб5!I10) -> #DIV/0! | K2: =Таб6!J7*Таб6!J35/273/(3600*Таб5!J10) -> #DIV/0! | L2: =Таб6!K7*Таб6!K35/273/(3600*Таб5!K10) -> #DIV/0! | M2: =Таб6!L7*Таб6!L35/273/(3600*Таб5!L10) -> #DIV/0!
A3: Средняя скорость потока газов в зоне | C3: м/с | D3: =IF(D2>=3,"МНОГО!",IF(D2<1.5,"МАЛО!","ПРАВИЛЬНО!")) -> ПРАВИЛЬНО! | E3: =IF(E2>=3,"МНОГО!",IF(E2<1.5,"МАЛО!","ПРАВИЛЬНО!")) -> МАЛО! | F3: =IF(F2>=1.5,"МНОГО!",IF(F2<0.5,"МАЛО!","ПРАВИЛЬНО!")) -> МНОГО! | G3: =IF(G2>=2,"МНОГО!",IF(G2<0.5,"МАЛО!","ПРАВИЛЬНО!")) -> ПРАВИЛЬНО! | H3: =IF(H2>=5,"МНОГО!",IF(H2<2,"МАЛО!","ПРАВИЛЬНО!")) -> МАЛО! | I3: =IF(I2>=5,"МНОГО!",IF(I2<2,"МАЛО!","ПРАВИЛЬНО!")) -> МАЛО! | J3: =IF(J2>=5,"МНОГО!",IF(J2<2,"МАЛО!","ПРАВИЛЬНО!")) -> #DIV/0! | K3: =IF(K2>=5,"МНОГО!",IF(K2<2,"МАЛО!","ПРАВИЛЬНО!")) -> #DIV/0! | L3: =IF(L2>=5,"МНОГО!",IF(L2<2,"МАЛО!","ПРАВИЛЬНО!")) -> #DIV/0! | M3: =IF(M2>=5,"МНОГО!",IF(M2<2,"МАЛО!","ПРАВИЛЬНО!")) -> #DIV/0!
A4: Рекомендуемые параметры | C4: м/с | D4: 1,5 ÷ 3,0 | E4: 1,5 ÷ 3,0 | F4: 0,5 ÷ 1,5 | G4: 0,5 ÷ 1,5 | H4: 2,0 ÷ 5,0 | I4: 2,0 ÷ 5,0 | J4: 2,0 ÷ 5,0 | K4: 2,0 ÷ 5,0 | L4: 2,0 ÷ 5,0 | M4: 2,0 ÷ 5,0
A5: Объем газового пространсва в зоне | C5: м3 | D5: =Таб2!C4*Таб5!C10 -> 86.729115 | E5: =Таб2!D4*Таб5!D10 -> 902.58 | F5: =Таб2!E4*Таб5!E10 -> 131.69599 | G5: =Таб2!F4*Таб5!F10 -> 293.25 | H5: =Таб2!G4*Таб5!G10 -> 44.03 | I5: =Таб2!H4*Таб5!H10 -> 293.25 | J5: =Таб2!I4*Таб5!I10 -> 0 | K5: =Таб2!J4*Таб5!J10 -> 0 | ... M5: =Таб2!L4*Таб5!L10 -> 0
A6: Эффективная толщина излучающего слоя | C6: м | D6: =3.6*D5/Таб5!C7 -> 5.2627334 | E6: =3.6*E5/Таб5!D7 -> 6.9339097 | F6: =3.6*F5/Таб5!E7 -> 5.5512265 | G6: =3.6*G5/Таб5!F7 -> 2.9130795 | H6: =3.6*H5/Таб5!G5 -> 3.5603774 | I6: =3.6*I5/Таб5!H7 -> 2.9130795 | J6: =3.6*J5/Таб5!I7 -> #DIV/0! | K6: =3.6*K5/Таб5!J7 -> #DIV/0! | L6: =3.6*L5/Таб5!K7 -> #DIV/0! | M6: =3.6*M5/Таб5!L7 -> #DIV/0! | N6: Кузнецов НВ (7-53) стр. 43
A7: Эквивалентный диаметр проходного сечения газов | C7: м | D7: =4*Таб5!C10/D8 -> 5.8474815 | E7: =4*Таб5!D10/E8 -> 7.7043441 | F7: =4*Таб5!E10/F8 -> 6.1680295 | G7: =4*Таб5!F10/G8 -> 3.236755 | H7: =4*Таб5!G10/H8 -> 3.9559748 | I7: =4*Таб5!H10/I8 -> 3.236755 | J7: =4*Таб5!I10/J8 -> #DIV/0! | K7: =4*Таб5!J10/K8 -> #DIV/0! | ... M7: =4*Таб5!L10/M8 -> #DIV/0!
A8: Периметр проходного сечения газов | C8: м | D8: =Таб5!C7/Таб2!C4 -> 23.731 | E8: =Таб5!D7/Таб2!D4 -> 38.160289 | F8: =Таб5!E7/Таб2!E4 -> 11.235355 | G8: =Таб5!F7/Таб2!F4 -> 26.26087 | H8: =Таб5!G5/Таб2!G4 -> 31.8 | I8: =Таб5!H7/Таб2!H4 -> 26.26087 | J8: =Таб5!I7/Таб2!I4 -> #DIV/0! | K8: =Таб5!J7/Таб2!J4 -> #DIV/0! | L8: =Таб5!K7/Таб2!K4 -> #DIV/0! | M8: =Таб5!L7/Таб2!L4 -> #DIV/0!
A9: Сумма объемных долей трехатомных газов | D9: =Таб6!C8+Таб6!C12+Таб6!C18 -> 0.65914692 | E9: =Таб6!D8+Таб6!D12+Таб6!D18 -> 0.65603774 | F9: =Таб6!E8+Таб6!E12+Таб6!E18 -> 0.63506849 | G9: =Таб6!F8+Таб6!F12+Таб6!F18 -> 0.61813333 | H9: =Таб6!G8+Таб6!G12+Таб6!G18 -> 0.61813333 | I9: =Таб6!H8+Таб6!H12+Таб6!H18 -> 0.61268722 | J9: =Таб6!I8+Таб6!I12+Таб6!I18 -> 0.60839895 | K9: =Таб6!J8+Таб6!J12+Таб6!J18 -> 0.60627724 | ... M9: =Таб6!L8+Таб6!L12+Таб6!L18 -> 0.60469565
A10: Давление технологических газов на выходе из зоны | C10: кгс/м2 | D10: =Таб1!$C$9-(Таб1!$C$9-Таб1!$C$10)*Таб2!C4/SUM(Таб2!C4:$I4) -> 9975.4909 | E10: =Таб1!$C$9-(Таб1!$C$9-Таб1!$C$10)*Таб2!D4/SUM(Таб2!D4:$I4) -> 9874.2475 | F10: =Таб1!$C$9-(Таб1!$C$9-Таб1!$C$10)*Таб2!E4/SUM(Таб2!E4:$I4) -> 9896.0077 | G10: =Таб1!$C$9-(Таб1!$C$9-Таб1!$C$10)*Таб2!F4/SUM(Таб2!F4:$I4) -> 9761.9691 | H10: =Таб1!$C$9-(Таб1!$C$9-Таб1!$C$10)*Таб2!G4/SUM(Таб2!G4:$I4) -> 9953.7744 | I10: =Таб1!$C$9-(Таб1!$C$9-Таб1!$C$10)*Таб2!H4/SUM(Таб2!H4:$I4) -> 9500 | J10: =Таб1!$C$9-(Таб1!$C$9-Таб1!$C$10)*Таб2!I4/SUM(Таб2!I4:$I4) -> #DIV/0! | K10: =Таб1!$C$9-(Таб1!$C$9-Таб1!$C$10)*Таб2!J4/SUM(Таб2!$I4:J4) -> #DIV/0! | L10: =Таб1!$C$9-(Таб1!$C$9-Таб1!$C$10)*Таб2!K4/SUM(Таб2!$I4:K4) -> #DIV/0! | M10: =Таб1!$C$9-(Таб1!$C$9-Таб1!$C$10)*Таб2!L4/SUM(Таб2!$I4:L4) -> #DIV/0!
A11: Коэффициент ослабления лучей трехатомными газами | C11: 1/(м*кгс/см2) | D11: =((0.78+1.6*Таб6!C12)/SQRT(D10*10^-4*D9*D6)-0.1)*(1-0.37*(Таб6!C24+273)/1000)*D9 -> 0.18516099 | E11: =((0.78+1.6*Таб6!D12)/SQRT(E10*10^-4*E9*E6)-0.1)*(1-0.37*(Таб6!D24+273)/1000)*E9 -> 0.21397529 | F11: =((0.78+1.6*Таб6!E12)/SQRT(F10*10^-4*F9*F6)-0.1)*(1-0.37*(Таб6!E24+273)/1000)*F9 -> 0.24597734 | G11: =((0.78+1.6*Таб6!F12)/SQRT(G10*10^-4*G9*G6)-0.1)*(1-0.37*(Таб6!F24+273)/1000)*G9 -> 0.37751645 | H11: =((0.78+1.6*Таб6!G12)/SQRT(H10*10^-4*H9*H6)-0.1)*(1-0.37*(Таб6!G24+273)/1000)*H9 -> 0.33551898 | I11: =((0.78+1.6*Таб6!H12)/SQRT(I10*10^-4*I9*I6)-0.1)*(1-0.37*(Таб6!H24+273)/1000)*I9 -> 0.3966049 | J11: =((0.78+1.6*Таб6!I12)/SQRT(J10*10^-4*J9*J6)-0.1)*(1-0.37*(Таб6!I24+273)/1000)*J9 -> #DIV/0! | K11: =((0.78+1.6*Таб6!J12)/SQRT(K10*10^-4*K9*K6)-0.1)*(1-0.37*(Таб6!J24+273)/1000)*K9 -> #DIV/0! | ... M11: =((0.78+1.6*Таб6!L12)/SQRT(M10*10^-4*M9*M6)-0.1)*(1-0.37*(Таб6!L24+273)/1000)*M9 -> #DIV/0! | N11: Кузнецов НВ (6-08) стр. 25
A12: Коэффициент ослабления лучей пылевыми частицами | C12: 1/(м*кгс/см2) | D12: =4300*Таб6!C20*D15/(Таб6!C35*(IF(Таб1!$C$2=Пр7!$A$14,Таб1!$C$8,Таб1!$C$7)))^(2/3) -> 0.11387241 | E12: =4300*Таб6!D20*E15/(Таб6!D35*(IF(Таб1!$C$2=Пр7!$A$14,Таб1!$C$8,Таб1!$C$7)))^(2/3) -> 0.10139966 | F12: =4300*Таб6!E20*F15/(Таб6!E35*(IF(Таб1!$C$2=Пр7!$A$14,Таб1!$C$8,Таб1!$C$7)))^(2/3) -> 0.10349875 | G12: =4300*Таб6!F20*G15/(Таб6!F35*(IF(Таб1!$C$2=Пр7!$A$14,Таб1!$C$8,Таб1!$C$7)))^(2/3) -> 0.10602142 | H12: =4300*Таб6!G20*H15/(Таб6!G35*(IF(Таб1!$C$2=Пр7!$A$14,Таб1!$C$8,Таб1!$C$7)))^(2/3) -> 0.10904669 | I12: =4300*Таб6!H20*I15/(Таб6!H35*(IF(Таб1!$C$2=Пр7!$A$14,Таб1!$C$8,Таб1!$C$7)))^(2/3) -> 0.11044155 | J12: =4300*Таб6!I20*J15/(Таб6!I35*(IF(Таб1!$C$2=Пр7!$A$14,Таб1!$C$8,Таб1!$C$7)))^(2/3) -> 0.11224644 | K12: =4300*Таб6!J20*K15/(Таб6!J35*(IF(Таб1!$C$2=Пр7!$A$14,Таб1!$C$8,Таб1!$C$7)))^(2/3) -> 0.11225188 | ... M12: =4300*Таб6!L20*M15/(Таб6!L35*(IF(Таб1!$C$2=Пр7!$A$14,Таб1!$C$8,Таб1!$C$7)))^(2/3) -> 0.10981606 | N12: Кузнецов НВ (6-13) стр. 25
A13: Суммарная сила поглощения запыленного потока | C13: 1/(м*кгс/см2) | D13: =D11+D12*D15 -> 0.18760845 | E13: =E11+E12*E15 -> 0.21569722 | F13: =F11+F12*F15 -> 0.24762655 | G13: =G11+G12*G15 -> 0.37909202 | H13: =H11+H12*H15 -> 0.33708964 | I13: =I11+I12*I15 -> 0.39812203 | J13: =J11+J12*J15 -> #DIV/0! | K13: =K11+K12*K15 -> #DIV/0! | ... M13: =M11+M12*M15 -> #DIV/0!
A14: Запыленность газов | C14: г/м3 | D14: =0.95*Таб1!$C$11 -> 33.25 | E14: =0.75*Таб1!$C$11 -> 26.25 | F14: =0.7*Таб1!$C$11 -> 24.5 | G14: =0.65*Таб1!$C$11 -> 22.75 | H14: =0.63*Таб1!C11 -> 22.05 | I14: =0.6*Таб1!C11 -> 21 | J14: =0.59*Таб1!$C$11 -> 20.65 | K14: =0.58*Таб1!$C$11 -> 20.3 | L14: =0.57*Таб1!$C$11 -> 19.95 | M14: =0.56*Таб1!$C$11 -> 19.6
A15: Безразмерная концентрация пыли в дымовых газах | C15: кг/кг | D15: =D14/Таб6!C20/1000 -> 0.021493039 | E15: =E14/Таб6!D20/1000 -> 0.016981626 | F15: =F14/Таб6!E20/1000 -> 0.015934621 | G15: =G14/Таб6!F20/1000 -> 0.014860879 | H15: =H14/Таб6!G20/1000 -> 0.014403621 | I15: =I14/Таб6!H20/1000 -> 0.013736975 | J15: =J14/Таб6!I20/1000 -> 0.01352296 | K15: =K14/Таб6!J20/1000 -> 0.013301033 | ... M15: =M14/Таб6!L20/1000 -> 0.012847619 | N15: Кузнецов НВ (4-11) стр. 16
A16: Суммарная оптическая толщина запыленного потока | D16: =D13*D10*10^-4*D6 -> 0.98491339 | E16: =E13*E10*10^-4*E6 -> 1.4768172 | F16: =F13*F10*10^-4*F6 -> 1.360336 | G16: =G13*G10*10^-4*G6 -> 1.0780388 | H16: =H13*H10*10^-4*H6 -> 1.1946185 | I16: =I13*I10*10^-4*I6 -> 1.1017731 | J16: =J13*J10*10^-4*J6 -> #DIV/0! | K16: =K13*K10*10^-4*K6 -> #DIV/0! | ... M16: =M13*M10*10^-4*M6 -> #DIV/0! | N16: Кузнецов НВ (7-52) стр. 43
A17: Степень черноты потока газов | C17: - | D17: =1-EXP(-D13*D10*10^-4*D6) -> 0.62652843 | E17: =1-EXP(-E13*E10*10^-4*E6) -> 0.77163663 | F17: =1-EXP(-F13*F10*10^-4*F6) -> 0.74342544 | G17: =1-EXP(-G13*G10*10^-4*G6) -> 0.65973782 | H17: =1-EXP(-H13*H10*10^-4*H6) -> 0.69718054 | I17: =1-EXP(-I13*I10*10^-4*I6) -> 0.6677186 | J17: =1-EXP(-J13*J10*10^-4*J6) -> #DIV/0! | K17: =1-EXP(-K13*K10*10^-4*K6) -> #DIV/0! | ... M17: =1-EXP(-M13*M10*10^-4*M6) -> #DIV/0! | N17: Кузнецов НВ (6-06) стр. 24 (7-51) стр. 43
A18: Средний температурный напор | C18: оС | D18: =((Таб1!C5-Таб4!$D$3)-(Таб6!C24-Таб4!$D$3))/LN((Таб1!C5-Таб4!$D$3)/(Таб6!C24-Таб4!$D$3)) -> 958.44361 | E18: =((Таб6!C24-Таб4!$D$3)-(Таб6!D24-Таб4!$D$3))/LN((Таб6!C24-Таб4!$D$3)/(Таб6!D24-Таб4!$D$3)) -> 668.96259 | F18: =((Таб6!D24-Таб4!$D$3)-(Таб6!E24-Таб4!$D$3))/LN((Таб6!D24-Таб4!$D$3)/(Таб6!E24-Таб4!$D$3)) -> 435.16616 | G18: =((Таб6!E24-Таб4!$D$3)-(Таб6!F24-Таб4!$D$3))/LN((Таб6!E24-Таб4!$D$3)/(Таб6!F24-Таб4!$D$3)) -> 327.45611 | H18: =((Таб6!F24-Таб4!$D$3)-(Таб6!G24-Таб4!$D$3))/LN((Таб6!F24-Таб4!$D$3)/(Таб6!G24-Таб4!$D$3)) -> 256.46068 | I18: =((Таб6!G24-Таб4!$D$3)-(Таб6!H24-Таб4!$D$3))/LN((Таб6!G24-Таб4!$D$3)/(Таб6!H24-Таб4!$D$3)) -> 213.53635 | J18: =((Таб6!H24-Таб4!$D$3)-(Таб6!I24-Таб4!$D$3))/LN((Таб6!H24-Таб4!$D$3)/(Таб6!I24-Таб4!$D$3)) -> #DIV/0! | K18: =((Таб6!I24-Таб4!$D$3)-(Таб6!J24-Таб4!$D$3))/LN((Таб6!I24-Таб4!$D$3)/(Таб6!J24-Таб4!$D$3)) -> #DIV/0! | L18: =((Таб6!J24-Таб4!$D$3)-(Таб6!K24-Таб4!$D$3))/LN((Таб6!J24-Таб4!$D$3)/(Таб6!K24-Таб4!$D$3)) -> #DIV/0! | M18: =((Таб6!K24-Таб4!$D$3)-(Таб6!L24-Таб4!$D$3))/LN((Таб6!K24-Таб4!$D$3)/(Таб6!L24-Таб4!$D$3)) -> #DIV/0!
A19: Расчетная температура потоков газов | C19: оС | D19: =Таб4!$D$3+D18 -> 1209.4436 | E19: =Таб4!$D$3+E18 -> 919.96259 | F19: =Таб4!$D$3+F18 -> 686.16616 | G19: =Таб4!$D$3+G18 -> 578.45611 | H19: =Таб4!$D$3+H18 -> 507.46068 | I19: =Таб4!$D$3+I18 -> 464.53635 | J19: =Таб4!$D$3+J18 -> #DIV/0! | K19: =Таб4!$D$3+K18 -> #DIV/0! | ... M19: =Таб4!$D$3+M18 -> #DIV/0! | N19: Кузнецов НВ п. 7-18 стр. 39
C20: К | D20: =D19+273 -> 1482.4436 | E20: =E19+273 -> 1192.9626 | F20: =F19+273 -> 959.16616 | G20: =G19+273 -> 851.45611 | H20: =H19+273 -> 780.46068 | I20: =I19+273 -> 737.53635 | J20: =J19+273 -> #DIV/0! | K20: =K19+273 -> #DIV/0! | ... M20: =M19+273 -> #DIV/0!
A21: Температура технологических газов на выходе | C21: оС | D21: =Таб1!C5-Таб2!C19 -> 1170 | E21: =Таб8_Расчет_коэффициента_теплопередачи[[#This Row],[Зона 1]]-Таб2!D19 -> 720 | F21: =Таб8_Расчет_коэффициента_теплопередачи[[#This Row],[Зона 2]]-Таб2!E19 -> 654 | G21: =Таб8_Расчет_коэффициента_теплопередачи[[#This Row],[Зона 3]]-Таб2!F19 -> 513 | H21: =Таб8_Расчет_коэффициента_теплопередачи[[#This Row],[Зона 4]]-Таб2!G19 -> 502 | I21: =Таб8_Расчет_коэффициента_теплопередачи[[#This Row],[Зона 5]]-Таб2!H19 -> 431 | J21: =Таб8_Расчет_коэффициента_теплопередачи[[#This Row],[Зона 6]]-Таб2!I19 -> 431 | K21: =Таб8_Расчет_коэффициента_теплопередачи[[#This Row],[Зона 7]]-Таб2!J19 -> 431 | L21: =Таб8_Расчет_коэффициента_теплопередачи[[#This Row],[Зона 8]]-Таб2!K19 -> 431 | M21: =Таб8_Расчет_коэффициента_теплопередачи[[#This Row],[Зона 9]]-Таб2!L19 -> 431
A22: Коэффициент теплоотдачи излучением от газов к листу | C22: ккал/(м2*ч*оС) | D22: =4.88*(10^(-8))*(Таб5!C2+1)/2*D17*(Таб6!C35^3)*((1-(D28/D20)^4)/(1-D28/D20)) -> 262.3175 | E22: =4.88*(10^(-8))*(Таб5!D2+1)/2*E17*(Таб6!D35^3)*((1-(E28/E20)^4)/(1-E28/E20)) -> 159.35662 | F22: =4.88*(10^(-8))*(Таб5!E2+1)/2*F17*(Таб6!E35^3)*((1-(F28/F20)^4)/(1-F28/F20)) -> 101.49764 | G22: =4.88*(10^(-8))*(Таб5!F2+1)/2*G17*(Таб6!F35^3)*((1-(G28/G20)^4)/(1-G28/G20)) -> 57.661284 | H22: =4.88*(10^(-8))*(Таб5!G2+1)/2*H17*(Таб6!G35^3)*((1-(H28/H20)^4)/(1-H28/H20)) -> 48.202487 | I22: =4.88*(10^(-8))*(Таб5!H2+1)/2*I17*(Таб6!H35^3)*((1-(I28/I20)^4)/(1-I28/I20)) -> 36.859333 | J22: =4.88*(10^(-8))*(Таб5!I2+1)/2*J17*(Таб6!I35^3)*((1-(J28/J20)^4)/(1-J28/J20)) -> #DIV/0! | K22: =4.88*(10^(-8))*(Таб5!J2+1)/2*K17*(Таб6!J35^3)*((1-(K28/K20)^4)/(1-K28/K20)) -> #DIV/0! | ... M22: =4.88*(10^(-8))*(Таб5!L2+1)/2*M17*(Таб6!L35^3)*((1-(M28/M20)^4)/(1-M28/M20)) -> #DIV/0! | N22: Кузнецов НВ (7-49) стр. 43
A23: Коэффициент сохранения тепла | D23: =1-Таб7!C20 -> 0.99175005 | E23: =1-Таб7!D20 -> 0.98127406 | F23: =1-Таб7!E20 -> 0.98471093 | G23: =1-Таб7!F20 -> 0.98192397 | H23: =1-Таб7!G20 -> 0.97683994 | I23: =1-Таб7!H20 -> 0.96615228 | J23: =1-Таб7!I20 -> #DIV/0! | K23: =1-Таб7!J20 -> #DIV/0! | ... M23: =1-Таб7!L20 -> #DIV/0! | N23: Кузнецов НВ (5-11) стр. 21
A24: Плотность потока с учетом коэффициента сохранения тепла | C24: ккал/(м2*ч) | D24: =Таб6!C38/Таб5!C7*D23*1000000 -> 25682.468 | E24: =Таб6!D38/Таб5!D7*E23*1000000 -> 16286.984 | F24: =Таб6!E38/Таб5!E7*F23*1000000 -> 9461.0163 | G24: =Таб6!F38/Таб5!F7*G23*1000000 -> 5733.5243 | H24: =Таб6!G38/Таб5!G7*H23*1000000 -> 4017.4548 | I24: =Таб6!H38/Таб5!H7*I23*1000000 -> 3012.7502 | J24: =Таб6!I38/Таб5!I7*J23*1000000 -> #DIV/0! | K24: =Таб6!J38/Таб5!J7*K23*1000000 -> #DIV/0! | ... M24: =Таб6!L38/Таб5!L7*M23*1000000 -> #DIV/0! | Q24: =3600/4190*Таб8_Расчет_коэффициента_теплопередачи[[#This Row],[Зона 1]] -> 22066.083
A25: Коэффициент загрязнения поверхности нагрева | B25: ε | C25: (м2*ч*оС)/ккал | D25: =IF(Таб6!C34>600,3*10^-5*Таб6!C34-0.0109,0.005) -> 0.0254 | E25: =IF(Таб6!D34>600,3*10^-5*Таб6!D34-0.0109,0.005) -> 0.01805 | F25: =IF(Таб6!E34>600,3*10^-5*Таб6!E34-0.0109,0.005) -> 0.013385 | G25: =IF(Таб6!F34>600,3*10^-5*Таб6!F34-0.0109,0.005) -> 0.0089375 | H25: =IF(Таб6!G34>600,3*10^-5*Таб6!G34-0.0109,0.005) -> 0.005 | I25: =IF(Таб6!H34>600,3*10^-5*Таб6!H34-0.0109,0.005) -> 0.005 | J25: =IF(Таб6!I34>600,3*10^-5*Таб6!I34-0.0109,0.005) -> 0.005 | K25: =IF(Таб6!J34>600,3*10^-5*Таб6!J34-0.0109,0.005) -> 0.005 | ... M25: =IF(Таб6!L34>600,3*10^-5*Таб6!L34-0.0109,0.005) -> 0.005 | N25: Кузнецов Н.В. Табл. 6-2 стр. 29 Кузнецов НВ п. 7-36 стр. 44 рис. 7-9 а) (7-73) стр. 47 Воинов А.П. стр. 131
A26: Кэффициент тепловой эффективности | B26: Ψ | N26: Кузнецов НВ таб. 7-3 стр. 48 Воинов АП (5.49) стр. 131
A27: Температура загрязненной поверхности стенки с учетом коэффициента загрязнения | B27: Tз | C27: оС | D27: =Таб4!$D$3+D25*D24 -> 903.3347 | E27: =Таб4!$D$3+E25*E24 -> 544.98006 | F27: =Таб4!$D$3+F25*F24 -> 377.6357 | G27: =Таб4!$D$3+G25*G24 -> 302.24337 | H27: =Таб4!$D$3+H25*H24 -> 271.08727 | I27: =Таб4!$D$3+I25*I24 -> 266.06375 | J27: =Таб4!$D$3+J25*J24 -> #DIV/0! | K27: =Таб4!$D$3+K25*K24 -> #DIV/0! | ... M27: =Таб4!$D$3+M25*M24 -> #DIV/0! | N27: Кузнецов НВ п. 7-36 (7-56) стр. 44
C28: К | D28: =D27+273 -> 1176.3347 | E28: =E27+273 -> 817.98006 | F28: =F27+273 -> 650.6357 | G28: =G27+273 -> 575.24337 | H28: =H27+273 -> 544.08727 | I28: =I27+273 -> 539.06375 | J28: =J27+273 -> #DIV/0! | K28: =K27+273 -> #DIV/0! | ... M28: =M27+273 -> #DIV/0!
A29: λSO2 | B29: λSO2 | C29: Вт/(м*оС) | D29: =-4*10^-9*D$19^2+5*10^-5*D$19+0.0082 -> 0.062821165 | E29: =-4*10^-9*E$19^2+5*10^-5*E$19+0.0082 -> 0.050812805 | F29: =-4*10^-9*F$19^2+5*10^-5*F$19+0.0082 -> 0.040625012 | G29: =-4*10^-9*G$19^2+5*10^-5*G$19+0.0082 -> 0.03578436 | H29: =-4*10^-9*H$19^2+5*10^-5*H$19+0.0082 -> 0.032542969 | I29: =-4*10^-9*I$19^2+5*10^-5*I$19+0.0082 -> 0.030563641 | J29: =-4*10^-9*J$19^2+5*10^-5*J$19+0.0082 -> #DIV/0! | K29: =-4*10^-9*K$19^2+5*10^-5*K$19+0.0082 -> #DIV/0! | ... M29: =-4*10^-9*M$19^2+5*10^-5*M$19+0.0082 -> #DIV/0! | N29: Бабичев Т.15.2 С.345.
A30: λSO3 | B30: λSO3 | C30: Вт/(м*оС) | D30: =-4*10^-9*D$19^2+5*10^-5*D$19+0.0082 -> 0.062821165 | E30: =-4*10^-9*E$19^2+5*10^-5*E$19+0.0082 -> 0.050812805 | F30: =-4*10^-9*F$19^2+5*10^-5*F$19+0.0082 -> 0.040625012 | G30: =-4*10^-9*G$19^2+5*10^-5*G$19+0.0082 -> 0.03578436 | H30: =-4*10^-9*H$19^2+5*10^-5*H$19+0.0082 -> 0.032542969 | I30: =-4*10^-9*I$19^2+5*10^-5*I$19+0.0082 -> 0.030563641 | J30: =-4*10^-9*J$19^2+5*10^-5*J$19+0.0082 -> #DIV/0! | K30: =-4*10^-9*K$19^2+5*10^-5*K$19+0.0082 -> #DIV/0! | ... M30: =-4*10^-9*M$19^2+5*10^-5*M$19+0.0082 -> #DIV/0! | N30: Бабичев Т.15.2 С.345.
A31: λH2O | B31: λH2O | C31: Вт/(м*оС) | D31: =-5*10^-8*D$19^2+0.0002*D$19+0.0225 -> 0.19125103 | E31: =-5*10^-8*E$19^2+0.0002*E$19+0.0225 -> 0.16417596 | F31: =-5*10^-8*F$19^2+0.0002*F$19+0.0225 -> 0.13619203 | G31: =-5*10^-8*G$19^2+0.0002*G$19+0.0225 -> 0.12146065 | H31: =-5*10^-8*H$19^2+0.0002*H$19+0.0225 -> 0.11111632 | I31: =-5*10^-8*I$19^2+0.0002*I$19+0.0225 -> 0.10461757 | J31: =-5*10^-8*J$19^2+0.0002*J$19+0.0225 -> #DIV/0! | K31: =-5*10^-8*K$19^2+0.0002*K$19+0.0225 -> #DIV/0! | ... M31: =-5*10^-8*M$19^2+0.0002*M$19+0.0225 -> #DIV/0! | N31: Бабичев Т.15.2 С.345.
A32: λO2 | B32: λO2 | C32: Вт/(м*оС) | D32: =-4*10^-8*D$19^2+9*10^-5*D$19+0.024 -> 0.074339771 | E32: =-4*10^-8*E$19^2+9*10^-5*E$19+0.024 -> 0.072943386 | F32: =-4*10^-8*F$19^2+9*10^-5*F$19+0.024 -> 0.066921994 | G32: =-4*10^-8*G$19^2+9*10^-5*G$19+0.024 -> 0.062676591 | H32: =-4*10^-8*H$19^2+9*10^-5*H$19+0.024 -> 0.059370808 | I32: =-4*10^-8*I$19^2+9*10^-5*I$19+0.024 -> 0.057176511 | J32: =-4*10^-8*J$19^2+9*10^-5*J$19+0.024 -> #DIV/0! | K32: =-4*10^-8*K$19^2+9*10^-5*K$19+0.024 -> #DIV/0! | ... M32: =-4*10^-8*M$19^2+9*10^-5*M$19+0.024 -> #DIV/0! | N32: Бабичев Т.15.2 С.345.
A33: λN2 | B33: λN2 | C33: Вт/(м*оС) | D33: =-5*10^-8*D$19^2+9*10^-5*D$19+0.0231 -> 0.058812233 | E33: =-5*10^-8*E$19^2+9*10^-5*E$19+0.0231 -> 0.063580075 | F33: =-5*10^-8*F$19^2+9*10^-5*F$19+0.0231 -> 0.061313754 | G33: =-5*10^-8*G$19^2+9*10^-5*G$19+0.0231 -> 0.058430476 | H33: =-5*10^-8*H$19^2+9*10^-5*H$19+0.0231 -> 0.055895644 | I33: =-5*10^-8*I$19^2+9*10^-5*I$19+0.0231 -> 0.05411857 | J33: =-5*10^-8*J$19^2+9*10^-5*J$19+0.0231 -> #DIV/0! | K33: =-5*10^-8*K$19^2+9*10^-5*K$19+0.0231 -> #DIV/0! | ... M33: =-5*10^-8*M$19^2+9*10^-5*M$19+0.0231 -> #DIV/0! | N33: Бабичев Т.15.2 С.345.
A34: λCO2 | B34: λCO2 | C34: Вт/(м*оС) | D34: =-1*10^-8*D$19^2+8*10^-5*D$19+0.0145 -> 0.09662795 | E34: =-1*10^-8*E$19^2+8*10^-5*E$19+0.0145 -> 0.079633696 | F34: =-1*10^-8*F$19^2+8*10^-5*F$19+0.0145 -> 0.064685053 | G34: =-1*10^-8*G$19^2+8*10^-5*G$19+0.0145 -> 0.057430374 | H34: =-1*10^-8*H$19^2+8*10^-5*H$19+0.0145 -> 0.052521691 | I34: =-1*10^-8*I$19^2+8*10^-5*I$19+0.0145 -> 0.049504968 | J34: =-1*10^-8*J$19^2+8*10^-5*J$19+0.0145 -> #DIV/0! | K34: =-1*10^-8*K$19^2+8*10^-5*K$19+0.0145 -> #DIV/0! | ... M34: =-1*10^-8*M$19^2+8*10^-5*M$19+0.0145 -> #DIV/0! | N34: Бабичев Т.15.2 С.345.
A35: λСО | B35: λСО | C35: Вт/(м*оС) | D35: =-1*10^-8*D$19^2+7*10^-5*D$19+0.0233 -> 0.093333514 | E35: =-1*10^-8*E$19^2+7*10^-5*E$19+0.0233 -> 0.07923407 | F35: =-1*10^-8*F$19^2+7*10^-5*F$19+0.0233 -> 0.066623391 | G35: =-1*10^-8*G$19^2+7*10^-5*G$19+0.0233 -> 0.060445813 | H35: =-1*10^-8*H$19^2+7*10^-5*H$19+0.0233 -> 0.056247084 | I35: =-1*10^-8*I$19^2+7*10^-5*I$19+0.0233 -> 0.053659604 | J35: =-1*10^-8*J$19^2+7*10^-5*J$19+0.0233 -> #DIV/0! | K35: =-1*10^-8*K$19^2+7*10^-5*K$19+0.0233 -> #DIV/0! | ... M35: =-1*10^-8*M$19^2+7*10^-5*M$19+0.0233 -> #DIV/0! | N35: Бабичев Т.15.2 С.345.
A36: Коэффициент теплопроводности газов при tср | B36: λ | C36: Вт/(м*оС) | D36: =Таб6!C8*D29+Таб6!C10*D30+Таб6!C12*D31+Таб6!C14*D32+Таб6!C16*D33+Таб6!C18*D34 -> 0.10831574 | E36: =Таб6!D8*E29+Таб6!D10*E30+Таб6!D12*E31+Таб6!D14*E32+Таб6!D16*E33+Таб6!D18*E34 -> 0.096020518 | F36: =Таб6!E8*F29+Таб6!E10*F30+Таб6!E12*F31+Таб6!E14*F32+Таб6!E16*F33+Таб6!E18*F34 -> 0.081366413 | G36: =Таб6!F8*G29+Таб6!F10*G30+Таб6!F12*G31+Таб6!F14*G32+Таб6!F16*G33+Таб6!F18*G34 -> 0.073377785 | H36: =Таб6!G8*H29+Таб6!G10*H30+Таб6!G12*H31+Таб6!G14*H32+Таб6!G16*H33+Таб6!G18*H34 -> 0.067990942 | I36: =Таб6!H8*I29+Таб6!H10*I30+Таб6!H12*I31+Таб6!H14*I32+Таб6!H16*I33+Таб6!H18*I34 -> 0.064473083 | J36: =Таб6!I8*J29+Таб6!I10*J30+Таб6!I12*J31+Таб6!I14*J32+Таб6!I16*J33+Таб6!I18*J34 -> #DIV/0! | K36: =Таб6!J8*K29+Таб6!J10*K30+Таб6!J12*K31+Таб6!J14*K32+Таб6!J16*K33+Таб6!J18*K34 -> #DIV/0! | ... M36: =Таб6!L8*M29+Таб6!L10*M30+Таб6!L12*M31+Таб6!L14*M32+Таб6!L16*M33+Таб6!L18*M34 -> #DIV/0!
C37: ккал/(м*ч*°С) | D37: =0.859*D36 -> 0.093043223 | E37: =0.859*E36 -> 0.082481625 | F37: =0.859*F36 -> 0.069893749 | G37: =0.859*G36 -> 0.063031517 | H37: =0.859*H36 -> 0.058404219 | I37: =0.859*I36 -> 0.055382378 | J37: =0.859*J36 -> #DIV/0! | K37: =0.859*K36 -> #DIV/0! | ... M37: =0.859*M36 -> #DIV/0!
A38: λвоздух | B38: λ | C38: Вт/(м*оС) | D38: =-2*10^-8*D$19^2+7*10^-5*D$19+0.0245 -> 0.079905976 | E38: =-2*10^-8*E$19^2+7*10^-5*E$19+0.0245 -> 0.071970758 | F38: =-2*10^-8*F$19^2+7*10^-5*F$19+0.0245 -> 0.063115151 | G38: =-2*10^-8*G$19^2+7*10^-5*G$19+0.0245 -> 0.058299698 | H38: =-2*10^-8*H$19^2+7*10^-5*H$19+0.0245 -> 0.054871921 | I38: =-2*10^-8*I$19^2+7*10^-5*I$19+0.0245 -> 0.052701664 | J38: =-2*10^-8*J$19^2+7*10^-5*J$19+0.0245 -> #DIV/0! | K38: =-2*10^-8*K$19^2+7*10^-5*K$19+0.0245 -> #DIV/0! | ... M38: =-2*10^-8*M$19^2+7*10^-5*M$19+0.0245 -> #DIV/0! | N38: Бабичев Т.15.2 С.345.
A39: μSO2 | B39: μSO2 | C39: Па*с | D39: =-1*10^-11*D$19^2+5*10^-8*D$19+1*10^-5 -> 5.5844642e-05 | E39: =-1*10^-11*E$19^2+5*10^-8*E$19+1*10^-5 -> 4.7534818e-05 | F39: =-1*10^-11*F$19^2+5*10^-8*F$19+1*10^-5 -> 3.9600068e-05 | G39: =-1*10^-11*G$19^2+5*10^-8*G$19+1*10^-5 -> 3.5576691e-05 | H39: =-1*10^-11*H$19^2+5*10^-8*H$19+1*10^-5 -> 3.2797871e-05 | I39: =-1*10^-11*I$19^2+5*10^-8*I$19+1*10^-5 -> 3.1068877e-05 | J39: =-1*10^-11*J$19^2+5*10^-8*J$19+1*10^-5 -> #DIV/0! | K39: =-1*10^-11*K$19^2+5*10^-8*K$19+1*10^-5 -> #DIV/0! | ... M39: =-1*10^-11*M$19^2+5*10^-8*M$19+1*10^-5 -> #DIV/0! | N39: Бабичев Т.15.2 С.345.
A40: μSO3 | B40: μSO3 | C40: Па*с | D40: =-1*10^-11*D$19^2+5*10^-8*D$19+1*10^-5 -> 5.5844642e-05 | E40: =-1*10^-11*E$19^2+5*10^-8*E$19+1*10^-5 -> 4.7534818e-05 | F40: =-1*10^-11*F$19^2+5*10^-8*F$19+1*10^-5 -> 3.9600068e-05 | G40: =-1*10^-11*G$19^2+5*10^-8*G$19+1*10^-5 -> 3.5576691e-05 | H40: =-1*10^-11*H$19^2+5*10^-8*H$19+1*10^-5 -> 3.2797871e-05 | I40: =-1*10^-11*I$19^2+5*10^-8*I$19+1*10^-5 -> 3.1068877e-05 | J40: =-1*10^-11*J$19^2+5*10^-8*J$19+1*10^-5 -> #DIV/0! | K40: =-1*10^-11*K$19^2+5*10^-8*K$19+1*10^-5 -> #DIV/0! | ... M40: =-1*10^-11*M$19^2+5*10^-8*M$19+1*10^-5 -> #DIV/0! | N40: Бабичев Т.15.2 С.345.
...

Sheet Таб3
A1: Наименование | B1: Единица измерения | C1: SO2 | D1: SO3 | E1: H2O | F1: O2 | G1: N2 | H1: CO2 | I1: СО | J1: S | K1: Всего
A2: Объёмы компонентов газов из печи | B2: нм3/ч | C2: =Таб1!$C$15*$K$2 -> 7962.8 | D2: =Таб1!$C$16*$K$2 -> 0 | E2: =Таб1!$C$17*$K$2 -> 11818.4 | F2: =Таб1!$C$18*$K$2 -> 1700 | G2: =Таб1!$C$19*$K$2 -> 8656.4 | H2: =Таб1!$C$20*$K$2 -> 3862.4 | I2: =Таб1!$C$21*$K$2 -> 0 | J2: =Таб1!$C$22*$K$2 -> 0 | K2: =Таб1!$C$4 -> 34000
A3: Молярная масса компонентов | B3: кг/моль | C3: 64 | D3: 80 | E3: 18 | F3: 32 | G3: 28 | H3: 44 | I3: 28 | J3: 32
A4: Истинная теплоёмкость на входе в КУ | B4: кДж/(м3*оС) | C4: {=IFERROR(INDEX(Пр6_Теплоёмкость_различных_газов[SO2, кДж/(м3*оС)],MATCH(MIN(IF(Пр6_Теплоёмкость_различных_газов[Температура, 0С]>=Таб1!$C$5,Пр6_Теплоёмкость_различных_газов[Температура, 0С],"")),Пр6_Теплоёмкость_различных_газов[Температура, 0С],0),0),"Ошибка")} -> 2.2975 | D4: =C4 -> 2.2975 | E4: {=IFERROR(INDEX(Пр6_Теплоёмкость_различных_газов[H2O, кДж/(м3*оС)],MATCH(MIN(IF(Пр6_Теплоёмкость_различных_газов[Температура, 0С]>=Таб1!$C$5,Пр6_Теплоёмкость_различных_газов[Температура, 0С],"")),Пр6_Теплоёмкость_различных_газов[Температура, 0С],0),0),"Ошибка")} -> 1.77 | F4: {=IFERROR(INDEX(Пр6_Теплоёмкость_различных_газов[О2, кДж/(м3*оС)],MATCH(MIN(IF(Пр6_Теплоёмкость_различных_газов[Температура, 0С]>=Таб1!$C$5,Пр6_Теплоёмкость_различных_газов[Температура, 0С],"")),Пр6_Теплоёмкость_различных_газов[Температура, 0С],0),0),"Ошибка")} -> 1.4725 | G4: {=IFERROR(INDEX(Пр6_Теплоёмкость_различных_газов[N2, кДж/(м3*оС)],MATCH(MIN(IF(Пр6_Теплоёмкость_различных_газов[Температура, 0С]>=Таб1!$C$5,Пр6_Теплоёмкость_различных_газов[Температура, 0С],"")),Пр6_Теплоёмкость_различных_газов[Температура, 0С],0),0),"Ошибка")} -> 1.415 | H4: {=IFERROR(INDEX(Пр6_Теплоёмкость_различных_газов[СО2, кДж/(м3*оС)],MATCH(MIN(IF(Пр6_Теплоёмкость_различных_газов[Температура, 0С]>=Таб1!$C$5,Пр6_Теплоёмкость_различных_газов[Температура, 0С],"")),Пр6_Теплоёмкость_различных_газов[Температура, 0С],0),0),"Ошибка")} -> 2.285 | I4: {=IFERROR(INDEX(Пр6_Теплоёмкость_различных_газов[СО, кДж/(м3*оС)],MATCH(MIN(IF(Пр6_Теплоёмкость_различных_газов[Температура, 0С]>=Таб1!$C$5,Пр6_Теплоёмкость_различных_газов[Температура, 0С],"")),Пр6_Теплоёмкость_различных_газов[Температура, 0С],0),0),"Ошибка")} -> 1.4225 | J4: 0 | K4: =Таб1!$C$15*C4+Таб1!$C$16*D4+Таб1!$C$17*E4+Таб1!$C$18*F4+Таб1!$C$19*G4+Таб1!$C$20*H4+Таб1!$C$21*I4+Таб1!$C$22*Таб3_Свойства_газов[[#This Row],[S]] -> 1.8467865
A5: Объём газов с учетом подсосов воздуха в печь | B5: нм3/ч | C5: =C2+J2 -> 7962.8 | D5: =D2 -> 0 | E5: =E2 -> 11818.4 | F5: =F2+0.21*Таб1!C12*Таб1!C4-(0.5*I2+J2) -> 2057 | G5: =G2+0.79*Таб1!C12*Таб1!C4 -> 9999.4 | H5: =H2+I2 -> 3862.4 | I5: 0 | J5: 0 | K5: =SUM(C5,D5,E5,F5,G5,H5) -> 35700
A6: Доли компонентов с учетом подсосов воздуха в печь | B6: % | C6: =C5/$K$5 -> 0.22304762 | D6: =D5/$K$5 -> 0 | E6: =E5/$K$5 -> 0.33104762 | F6: =F5/$K$5 -> 0.057619048 | G6: =G5/$K$5 -> 0.28009524 | H6: =H5/$K$5 -> 0.10819048 | I6: =I5/$K$2 -> 0 | J6: =J5/$K$2 -> 0 | K6: =SUM(C6:J6) -> 1

Sheet Таб4
A1: Наименование | B1: Скрытая теплота парообразования | C1: Энтальпия насыщенного пара | D1: Температура пара на линии насыщения | E1: Энтальпия воды на линии насыщения | F1: Энтальпия питательной воды | G1: Энтальпия пара при Тгаз
A2: Единица измерения | B2: ккал/кг | C2: ккал/кг | D2: оC | E2: ккал/кг | F2: ккал/кг | G2: ккал/кг
A3: Значение | B3: {=IFERROR(INDEX(Пр3!$H$2:$H$398,MATCH(MIN(IF(Пр3!$B$2:$B$398>=Таб1!$C$23,Пр3!$B$2:$B$398,"")),Пр3!$B$2:$B$398,0),0),"Ошибка")/4.187} -> 408.04872 | C3: {=IFERROR(INDEX(Пр3!$G$2:$G$398,MATCH(MIN(IF(Пр3!$B$2:$B$398>=Таб1!$C$23,Пр3!$B$2:$B$398,"")),Пр3!$B$2:$B$398,0),0),"Ошибка")/4.187} -> 668.5455 | D3: {=IFERROR(INDEX(Пр3!$A$2:$A$398,MATCH(MIN(IF(Пр3!$B$2:$B$398>=Таб1!$C$23,Пр3!$B$2:$B$398,"")),Пр3!$B$2:$B$398,0),0),"Ошибка")} -> 251 | E3: {=IFERROR(INDEX(Пр3!$F$2:$F$398,MATCH(MIN(IF(Пр3!$B$2:$B$398>=Таб1!$C$23,Пр3!$B$2:$B$398,"")),Пр3!$B$2:$B$398,0),0),"Ошибка")/4.187} -> 260.49678 | F3: {=IFERROR(INDEX(Пр3!$F$2:$F$398,MATCH(MIN(IF(Пр3!$A$2:$A$398>=Таб1!$C$24,Пр3!$A$2:$A$398,"")),Пр3!$A$2:$A$398,0),0),"Ошибка")/4.187} -> 105.12778 | G3: {=IFERROR(INDEX(Пр3!$G$2:$G$398,MATCH(MIN(IF(Пр3!$A$2:$A$398>=Таб1!C6,Пр3!$A$2:$A$398,"")),Пр3!$A$2:$A$398,0),0),"Ошибка")/4.187} -> 597.32505

Sheet Таб5
A1: Наименование | B1: Единица измерения | C1: Зона 1 | D1: Зона 2 | E1: Зона 3 | F1: Зона 4 | G1: Зона 5 | H1: Зона 6 | I1: Зона 7 | J1: Зона 8 | K1: Зона 9 | L1: Зона 10 | M1: Зона XX
A2: Степень черноты стенки нагрева по зонам (листа ст.20К) | B2: - | C2: 0.8 | D2: 0.8 | E2: 0.8 | F2: 0.8 | G2: 0.8 | H2: 0.8 | I2: 0.8 | J2: 0.8 | K2: 0.8 | L2: 0.8 | M2: Кузнецов НВ п. 7-32 стр. 43
A3: Площадь боковых стен поверхности нагрева | B3: м2 | C3: =IF(Таб2!C3="Вертикальное",2*Таб2!C4*(Таб2!C5+Таб2!C6),2*Таб2!C4*Таб2!C6) -> 26.1075 | D3: =IF(Таб2!D3="Вертикальное",2*Таб2!D4*(Таб2!D5+Таб2!D6),2*Таб2!D4*Таб2!D6) -> 429.8 | E3: =IF(Таб2!E3="Вертикальное",2*Таб2!E4*(Таб2!E5+Таб2!E6),2*Таб2!E4*Таб2!E6) -> 50.1699 | F3: =IF(Таб2!F3="Вертикальное",2*Таб2!F4*(Таб2!F5+Таб2!F6),2*Таб2!F4*Таб2!F6) -> 186.3 | G3: =IF(Таб2!G3="Вертикальное",2*Таб2!G4*(Таб2!G5+Таб2!G6),2*Таб2!G4*Таб2!G6)+2*(SQRT((Таб2!G5/2)^2+Таб2!G7^2))*Таб2!G4 -> 20.653809 | H3: =IF(Таб2!H3="Вертикальное",2*Таб2!H4*(Таб2!H5+Таб2!H6),2*Таб2!H4*Таб2!H6) -> 186.3 | I3: =IF(Таб2!I3="Вертикальное",2*Таб2!I4*(Таб2!I5+Таб2!I6),2*Таб2!I4*Таб2!I6) -> 0 | J3: =IF(Таб2!J3="Вертикальное",2*Таб2!J4*(Таб2!J5+Таб2!J6),2*Таб2!J4*Таб2!J6) -> 0 | K3: =IF(Таб2!K3="Вертикальное",2*Таб2!K4*(Таб2!K5+Таб2!K6),2*Таб2!K4*Таб2!K6) -> 0 | L3: =IF(Таб2!L3="Вертикальное",2*Таб2!L4*(Таб2!L5+Таб2!L6),2*Таб2!L4*Таб2!L6) -> 0
A4: Площадь горизонтальных стен поверхности нагрева | B4: м2 | C4: =IF(Таб2!C3="Горизонтальный",2*Таб2!C4*Таб2!C5,"0,0") -> 0,0 | D4: =IF(Таб2!D3="Горизонтальный",2*Таб2!D4*Таб2!D5,"0,0") -> 0,0 | E4: =IF(Таб2!E3="Горизонтальный",2*Таб2!E4*Таб2!E5,"0,0") -> 0,0 | F4: =IF(Таб2!F3="Горизонтальный",2*Таб2!F4*Таб2!F5,"0,0") -> 0,0 | G4: =IF(Таб2!G3="Горизонтальный",2*Таб2!G4*Таб2!G5,"0,0") -> 0,0 | H4: =IF(Таб2!H3="Горизонтальный",2*Таб2!H4*Таб2!H5,"0,0") -> 0,0 | I4: =IF(Таб2!I3="Горизонтальный",2*Таб2!I4*Таб2!I5,"0,0") -> 0,0 | J4: =IF(Таб2!J3="Горизонтальный",2*Таб2!J4*Таб2!J5,"0,0") -> 0,0 | ... L4: =IF(Таб2!L3="Горизонтальный",2*Таб2!L4*Таб2!L5,"0,0") -> 0,0
A5: Площадь стеновой поверхности нагрева | B5: м2 | C5: =Таб2!C8 -> 59.3275 | D5: =Таб2!D8 -> 468.60835 | E5: =Таб2!E8 -> 85.40555 | F5: =Таб2!F8 -> 362.4 | G5: =Таб2!G8 -> 44.52 | H5: =Таб2!H8 -> 362.4 | I5: =I3+I4 -> 0 | J5: =J3+J4 -> 0 | K5: =K3+K4 -> 0 | L5: =L3+L4 -> 0
A6: Площадь ширмовой поверхности нагрева | B6: м2 | C6: =Таб2!C9 -> 0 | D6: =Таб2!D9 -> 0 | E6: =Таб2!E9 -> 0 | F6: =Таб2!F9 -> 0 | G6: =Таб2!G9 -> 0 | H6: =Таб2!H9 -> 0 | I6: =Таб2!I9 -> 0 | J6: =Таб2!J9 -> 0 | ... L6: =Таб2!L9 -> 0
A7: Площадь поверхности нагрева по зонам и всего | B7: м2 | C7: =C5+C6 -> 59.3275 | D7: =D5+D6 -> 468.60835 | E7: =E5+E6 -> 85.40555 | F7: =F5+F6 -> 362.4 | G7: =G5+G6 -> 44.52 | H7: =H5+H6 -> 362.4 | I7: =I5+I6 -> 0 | J7: =J5+J6 -> 0 | ... L7: =L5+L6 -> 0
A8: Доля стеновой поверхности | B8: % | C8: =C5/C7 -> 1 | D8: =D5/D7 -> 1 | E8: =E5/E7 -> 1 | F8: =F5/F7 -> 1 | G8: =G5/G7 -> 1 | H8: =H5/H7 -> 1 | I8: =I5/I7 -> #DIV/0! | J8: =J5/J7 -> #DIV/0! | ... L8: =L5/L7 -> #DIV/0!
A9: Доля ширмовой поверхности | B9: % | C9: =C6/C7 -> 0 | D9: =D6/D7 -> 0 | E9: =E6/E7 -> 0 | F9: =F6/F7 -> 0 | G9: =G6/G7 -> 0 | H9: =H6/H7 -> 0 | I9: =I6/I7 -> #DIV/0! | J9: =J6/J7 -> #DIV/0! | ... L9: =L6/L7 -> #DIV/0!
A10: Площадь проходного сечения по зонам | B10: м2 | C10: =Таб2!C5*Таб2!C6-Таб2!C$13*Таб2!C6*Таб2!C12 -> 34.691646 | D10: =Таб2!D5*Таб2!D6-Таб2!D$13*Таб2!D6*Таб2!D12 -> 73.5 | E10: =2*Таб2!E5*Таб2!E6-Таб2!E$13*Таб2!E6*Таб2!E12 -> 17.325 | F10: =2*Таб2!F5*Таб2!F6-Таб2!F$13*Таб2!F6*Таб2!F12 -> 21.25 | G10: =2*Таб2!G5*Таб2!G6-Таб2!G$13*Таб2!G6*Таб2!G12 -> 31.45 | H10: =2*Таб2!H5*Таб2!H6-Таб2!H$13*Таб2!H6*Таб2!H12 -> 21.25 | I10: =Таб2!I5*Таб2!I6-Таб2!I$13*Таб2!I6*Таб2!I12 -> 0 | J10: =Таб2!J5*Таб2!J6-Таб2!J$13*Таб2!J6*Таб2!J12 -> 0 | K10: =Таб2!K5*Таб2!K6-Таб2!K$13*Таб2!K6*Таб2!K12 -> 0 | L10: =Таб2!L5*Таб2!L6-Таб2!L$13*Таб2!L6*Таб2!L12 -> 0

Sheet Таб6
A1: Наименование | B1: Единица измерения | C1: Зона 1 | D1: Зона 2 | E1: Зона 3 | F1: Зона 4 | G1: Зона 5 | H1: Зона 6 | I1: Зона 7 | J1: Зона 8 | K1: Зона 9 | L1: Зона 10 | M1: Зона XX
A2: Количество газов на входе в зону | B2: м3/ч | C2: =Таб3!K5 -> 35700 | D2: =C6 -> 35870 | E2: =D6 -> 36040 | F2: =E6 -> 37230 | G2: =F6 -> 38250 | H2: =G6 -> 38250 | I2: =H6 -> 38590 | J2: =I6 -> 38862 | K2: =J6 -> 38998 | L2: =K6 -> 39066
A3: Доля присосов в зоне | B3: % | C3: 0.05 | D3: 0.05 | E3: 0.35 | F3: 0.3 | G3: 0 | H3: 0.1 | I3: 0.08 | J3: 0.04 | K3: 0.02 | L3: 0.01
B4: м3/ч | C4: =C3*Таб1!$C$13*Таб1!$C$4 -> 170 | D4: =D3*Таб1!$C$13*Таб1!$C$4 -> 170 | E4: =E3*Таб1!$C$13*Таб1!$C$4 -> 1190 | F4: =F3*Таб1!$C$13*Таб1!$C$4 -> 1020 | G4: =G3*Таб1!$C$13*Таб1!$C$4 -> 0 | H4: =H3*Таб1!$C$13*Таб1!$C$4 -> 340 | I4: =I3*Таб1!$C$13*Таб1!$C$4 -> 272 | J4: =J3*Таб1!$C$13*Таб1!$C$4 -> 136 | ... L4: =L3*Таб1!$C$13*Таб1!$C$4 -> 34
A5: Теплоёмкость воздуха | B5: кДж/ (м3*оС) | C5: {=IFERROR(INDEX(Пр6!$D$14:$D$123,MATCH(MIN(IF(Пр6!$A$14:$A$123>=Таб1!$C$14,Пр6!$A$14:$A$123,"")),Пр6!$A$14:$A$123,0),0),"Ошибка")} -> 1.33 | D5: {=IFERROR(INDEX(Пр6!$D$14:$D$123,MATCH(MIN(IF(Пр6!$A$14:$A$123>=Таб1!$C$14,Пр6!$A$14:$A$123,"")),Пр6!$A$14:$A$123,0),0),"Ошибка")} -> 1.33 | E5: {=IFERROR(INDEX(Пр6!$D$14:$D$123,MATCH(MIN(IF(Пр6!$A$14:$A$123>=Таб1!$C$14,Пр6!$A$14:$A$123,"")),Пр6!$A$14:$A$123,0),0),"Ошибка")} -> 1.33 | F5: {=IFERROR(INDEX(Пр6!$D$14:$D$123,MATCH(MIN(IF(Пр6!$A$14:$A$123>=Таб1!$C$14,Пр6!$A$14:$A$123,"")),Пр6!$A$14:$A$123,0),0),"Ошибка")} -> 1.33 | G5: {=IFERROR(INDEX(Пр6!$D$14:$D$123,MATCH(MIN(IF(Пр6!$A$14:$A$123>=Таб1!$C$14,Пр6!$A$14:$A$123,"")),Пр6!$A$14:$A$123,0),0),"Ошибка")} -> 1.33 | H5: {=IFERROR(INDEX(Пр6!$D$14:$D$123,MATCH(MIN(IF(Пр6!$A$14:$A$123>=Таб1!$C$14,Пр6!$A$14:$A$123,"")),Пр6!$A$14:$A$123,0),0),"Ошибка")} -> 1.33 | I5: {=IFERROR(INDEX(Пр6!$D$14:$D$123,MATCH(MIN(IF(Пр6!$A$14:$A$123>=Таб1!$C$14,Пр6!$A$14:$A$123,"")),Пр6!$A$14:$A$123,0),0),"Ошибка")} -> 1.33 | J5: {=IFERROR(INDEX(Пр6!$D$14:$D$123,MATCH(MIN(IF(Пр6!$A$14:$A$123>=Таб1!$C$14,Пр6!$A$14:$A$123,"")),Пр6!$A$14:$A$123,0),0),"Ошибка")} -> 1.33 | ... L5: {=IFERROR(INDEX(Пр6!$D$14:$D$123,MATCH(MIN(IF(Пр6!$A$14:$A$123>=Таб1!$C$14,Пр6!$A$14:$A$123,"")),Пр6!$A$14:$A$123,0),0),"Ошибка")} -> 1.33
A6: Количество газов на выходе | B6: м3/ч | C6: =SUM(C9,C11,C13,C15,C17,C19) -> 35870 | D6: =SUM(D9,D11,D13,D15,D17,D19) -> 36040 | E6: =SUM(E9,E11,E13,E15,E17,E19) -> 37230 | F6: =SUM(F9,F11,F13,F15,F17,F19) -> 38250 | G6: =SUM(G9,G11,G13,G15,G17,G19) -> 38250 | H6: =SUM(H9,H11,H13,H15,H17,H19) -> 38590 | I6: =SUM(I9,I11,I13,I15,I17,I19) -> 38862 | J6: =SUM(J9,J11,J13,J15,J17,J19) -> 38998 | ... L6: =SUM(L9,L11,L13,L15,L17,L19) -> 39100
A7: Среднее количество газов | B7: м3/ч | C7: =AVERAGE(C2,C6) -> 35785 | D7: =AVERAGE(D2,D6) -> 35955 | E7: =AVERAGE(E2,E6) -> 36635 | F7: =AVERAGE(F2,F6) -> 37740 | G7: =AVERAGE(G2,G6) -> 38250 | H7: =AVERAGE(H2,H6) -> 38420 | I7: =AVERAGE(I2,I6) -> 38726 | J7: =AVERAGE(J2,J6) -> 38930 | ... L7: =AVERAGE(L2,L6) -> 39083
A8: SO2 | B8: % | C8: =C9/C$6 -> 0.22199052 | D8: =D9/D$6 -> 0.2209434 | E8: =E9/E$6 -> 0.21388128 | F8: =F9/F$6 -> 0.20817778 | G8: =G9/G$6 -> 0.20817778 | H8: =H9/H$6 -> 0.20634361 | I8: =I9/I$6 -> 0.20489939 | J8: =J9/J$6 -> 0.20418483 | ... L8: =L9/L$6 -> 0.20365217
B9: м3/ч | C9: =Таб3!C5 -> 7962.8 | D9: =Таб6_Расчет_выхода_ВЭР[[#This Row],[Зона 1]] -> 7962.8 | E9: =Таб6_Расчет_выхода_ВЭР[[#This Row],[Зона 2]] -> 7962.8 | F9: =Таб6_Расчет_выхода_ВЭР[[#This Row],[Зона 3]] -> 7962.8 | G9: =Таб6_Расчет_выхода_ВЭР[[#This Row],[Зона 4]] -> 7962.8 | H9: =Таб6_Расчет_выхода_ВЭР[[#This Row],[Зона 5]] -> 7962.8 | I9: =Таб6_Расчет_выхода_ВЭР[[#This Row],[Зона 6]] -> 7962.8 | J9: =Таб6_Расчет_выхода_ВЭР[[#This Row],[Зона 7]] -> 7962.8 | K9: =Таб6_Расчет_выхода_ВЭР[[#This Row],[Зона 8]] -> 7962.8 | L9: =Таб6_Расчет_выхода_ВЭР[[#This Row],[Зона 9]] -> 7962.8
A10: SO3 | B10: % | C10: =C11/C$6 -> 0 | D10: =D11/D$6 -> 0 | E10: =E11/E$6 -> 0 | F10: =F11/F$6 -> 0 | G10: =G11/G$6 -> 0 | H10: =H11/H$6 -> 0 | I10: =I11/I$6 -> 0 | J10: =J11/J$6 -> 0 | ... L10: =L11/L$6 -> 0
B11: м3/ч | C11: =Таб3!D5 -> 0 | D11: =Таб6_Расчет_выхода_ВЭР[[#This Row],[Зона 1]] -> 0 | E11: =Таб6_Расчет_выхода_ВЭР[[#This Row],[Зона 2]] -> 0 | F11: =Таб6_Расчет_выхода_ВЭР[[#This Row],[Зона 3]] -> 0 | G11: =Таб6_Расчет_выхода_ВЭР[[#This Row],[Зона 4]] -> 0 | H11: =Таб6_Расчет_выхода_ВЭР[[#This Row],[Зона 5]] -> 0 | I11: =Таб6_Расчет_выхода_ВЭР[[#This Row],[Зона 6]] -> 0 | J11: =Таб6_Расчет_выхода_ВЭР[[#This Row],[Зона 7]] -> 0 | K11: =Таб6_Расчет_выхода_ВЭР[[#This Row],[Зона 8]] -> 0 | L11: =Таб6_Расчет_выхода_ВЭР[[#This Row],[Зона 9]] -> 0
A12: H2O | B12: % | C12: =C13/C$6 -> 0.32947867 | D12: =D13/D$6 -> 0.32792453 | E12: =E13/E$6 -> 0.31744292 | F12: =F13/F$6 -> 0.30897778 | G12: =G13/G$6 -> 0.30897778 | H12: =H13/H$6 -> 0.30625551 | I12: =I13/I$6 -> 0.30411199 | J12: =J13/J$6 -> 0.30305144 | ... L12: =L13/L$6 -> 0.30226087
B13: м3/ч | C13: =Таб3!E5 -> 11818.4 | D13: =Таб6_Расчет_выхода_ВЭР[[#This Row],[Зона 1]] -> 11818.4 | E13: =Таб6_Расчет_выхода_ВЭР[[#This Row],[Зона 2]] -> 11818.4 | F13: =Таб6_Расчет_выхода_ВЭР[[#This Row],[Зона 3]] -> 11818.4 | G13: =Таб6_Расчет_выхода_ВЭР[[#This Row],[Зона 4]] -> 11818.4 | H13: =Таб6_Расчет_выхода_ВЭР[[#This Row],[Зона 5]] -> 11818.4 | I13: =Таб6_Расчет_выхода_ВЭР[[#This Row],[Зона 6]] -> 11818.4 | J13: =Таб6_Расчет_выхода_ВЭР[[#This Row],[Зона 7]] -> 11818.4 | K13: =Таб6_Расчет_выхода_ВЭР[[#This Row],[Зона 8]] -> 11818.4 | L13: =Таб6_Расчет_выхода_ВЭР[[#This Row],[Зона 9]] -> 11818.4
A14: O2 | B14: % | C14: =C15/C$6 -> 0.058341232 | D14: =D15/D$6 -> 0.059056604 | E14: =E15/E$6 -> 0.063881279 | F14: =F15/F$6 -> 0.067777778 | G14: =G15/G$6 -> 0.067777778 | H14: =H15/H$6 -> 0.069030837 | I14: =I15/I$6 -> 0.070017498 | J14: =J15/J$6 -> 0.070505667 | ... L14: =L15/L$6 -> 0.070869565
B15: м3/ч | C15: =Таб3!F5+0.21*C4 -> 2092.7 | D15: =Таб6_Расчет_выхода_ВЭР[[#This Row],[Зона 1]]+0.21*D4 -> 2128.4 | E15: =Таб6_Расчет_выхода_ВЭР[[#This Row],[Зона 2]]+0.21*E4 -> 2378.3 | F15: =Таб6_Расчет_выхода_ВЭР[[#This Row],[Зона 3]]+0.21*F4 -> 2592.5 | G15: =Таб6_Расчет_выхода_ВЭР[[#This Row],[Зона 4]]+0.21*G4 -> 2592.5 | H15: =Таб6_Расчет_выхода_ВЭР[[#This Row],[Зона 5]]+0.21*H4 -> 2663.9 | I15: =Таб6_Расчет_выхода_ВЭР[[#This Row],[Зона 6]]+0.21*I4 -> 2721.02 | J15: =Таб6_Расчет_выхода_ВЭР[[#This Row],[Зона 7]]+0.21*J4 -> 2749.58 | K15: =Таб6_Расчет_выхода_ВЭР[[#This Row],[Зона 8]]+0.21*K4 -> 2763.86 | L15: =Таб6_Расчет_выхода_ВЭР[[#This Row],[Зона 9]]+0.21*L4 -> 2771
A16: N2 | B16: % | C16: =C17/C$6 -> 0.28251185 | D16: =D17/D$6 -> 0.28490566 | E16: =E17/E$6 -> 0.30105023 | F16: =F17/F$6 -> 0.31408889 | G16: =G17/G$6 -> 0.31408889 | H16: =H17/H$6 -> 0.31828194 | I16: =I17/I$6 -> 0.32158355 | J16: =J17/J$6 -> 0.32321709 | ... L16: =L17/L$6 -> 0.32443478
B17: м3/ч | C17: =Таб3!G5+0.79*C4 -> 10133.7 | D17: =Таб6_Расчет_выхода_ВЭР[[#This Row],[Зона 1]]+0.79*D4 -> 10268 | E17: =Таб6_Расчет_выхода_ВЭР[[#This Row],[Зона 2]]+0.79*E4 -> 11208.1 | F17: =Таб6_Расчет_выхода_ВЭР[[#This Row],[Зона 3]]+0.79*F4 -> 12013.9 | G17: =Таб6_Расчет_выхода_ВЭР[[#This Row],[Зона 4]]+0.79*G4 -> 12013.9 | H17: =Таб6_Расчет_выхода_ВЭР[[#This Row],[Зона 5]]+0.79*H4 -> 12282.5 | I17: =Таб6_Расчет_выхода_ВЭР[[#This Row],[Зона 6]]+0.79*I4 -> 12497.38 | J17: =Таб6_Расчет_выхода_ВЭР[[#This Row],[Зона 7]]+0.79*J4 -> 12604.82 | K17: =Таб6_Расчет_выхода_ВЭР[[#This Row],[Зона 8]]+0.79*K4 -> 12658.54 | L17: =Таб6_Расчет_выхода_ВЭР[[#This Row],[Зона 9]]+0.79*L4 -> 12685.4
A18: CO2 | B18: % | C18: =C19/C$6 -> 0.10767773 | D18: =D19/D$6 -> 0.10716981 | E18: =E19/E$6 -> 0.10374429 | F18: =F19/F$6 -> 0.10097778 | G18: =G19/G$6 -> 0.10097778 | H18: =H19/H$6 -> 0.10008811 | I18: =I19/I$6 -> 0.099387577 | J18: =J19/J$6 -> 0.099040976 | ... L18: =L19/L$6 -> 0.098782609
B19: м3/ч | C19: =Таб3!H5 -> 3862.4 | D19: =Таб6_Расчет_выхода_ВЭР[[#This Row],[Зона 1]] -> 3862.4 | E19: =Таб6_Расчет_выхода_ВЭР[[#This Row],[Зона 2]] -> 3862.4 | F19: =Таб6_Расчет_выхода_ВЭР[[#This Row],[Зона 3]] -> 3862.4 | G19: =Таб6_Расчет_выхода_ВЭР[[#This Row],[Зона 4]] -> 3862.4 | H19: =Таб6_Расчет_выхода_ВЭР[[#This Row],[Зона 5]] -> 3862.4 | I19: =Таб6_Расчет_выхода_ВЭР[[#This Row],[Зона 6]] -> 3862.4 | J19: =Таб6_Расчет_выхода_ВЭР[[#This Row],[Зона 7]] -> 3862.4 | K19: =Таб6_Расчет_выхода_ВЭР[[#This Row],[Зона 8]] -> 3862.4 | L19: =Таб6_Расчет_выхода_ВЭР[[#This Row],[Зона 9]] -> 3862.4
A20: Плотность газов | B20: кг/нм3 | C20: =(C8*Таб3!$C$3+C10*Таб3!$D$3+C12*Таб3!$E$3+C14*Таб3!$F$3+C16*Таб3!$G$3+C18*Таб3!$H$3)/22.4 -> 1.5470125 | D20: =(D8*Таб3!$C$3+D10*Таб3!$D$3+D12*Таб3!$E$3+D14*Таб3!$F$3+D16*Таб3!$G$3+D18*Таб3!$H$3)/22.4 -> 1.5457884 | E20: =(E8*Таб3!$C$3+E10*Таб3!$D$3+E12*Таб3!$E$3+E14*Таб3!$F$3+E16*Таб3!$G$3+E18*Таб3!$H$3)/22.4 -> 1.5375326 | F20: =(F8*Таб3!$C$3+F10*Таб3!$D$3+F12*Таб3!$E$3+F14*Таб3!$F$3+F16*Таб3!$G$3+F18*Таб3!$H$3)/22.4 -> 1.5308651 | G20: =(G8*Таб3!$C$3+G10*Таб3!$D$3+G12*Таб3!$E$3+G14*Таб3!$F$3+G16*Таб3!$G$3+G18*Таб3!$H$3)/22.4 -> 1.5308651 | H20: =(H8*Таб3!$C$3+H10*Таб3!$D$3+H12*Таб3!$E$3+H14*Таб3!$F$3+H16*Таб3!$G$3+H18*Таб3!$H$3)/22.4 -> 1.5287209 | I20: =(I8*Таб3!$C$3+I10*Таб3!$D$3+I12*Таб3!$E$3+I14*Таб3!$F$3+I16*Таб3!$G$3+I18*Таб3!$H$3)/22.4 -> 1.5270326 | J20: =(J8*Таб3!$C$3+J10*Таб3!$D$3+J12*Таб3!$E$3+J14*Таб3!$F$3+J16*Таб3!$G$3+J18*Таб3!$H$3)/22.4 -> 1.5261972 | ... L20: =(L8*Таб3!$C$3+L10*Таб3!$D$3+L12*Таб3!$E$3+L14*Таб3!$F$3+L16*Таб3!$G$3+L18*Таб3!$H$3)/22.4 -> 1.5255745
A21: Удельный объём | B21: нм3/кг | C21: =C20^-1 -> 0.64640718 | D21: =D20^-1 -> 0.64691907 | E21: =E20^-1 -> 0.65039271 | F21: =F20^-1 -> 0.65322543 | G21: =G20^-1 -> 0.65322543 | H21: =H20^-1 -> 0.65414164 | I21: =I20^-1 -> 0.65486488 | J21: =J20^-1 -> 0.65522331 | ... L21: =L20^-1 -> 0.65549075
A22: Энтальпия газов на входе в зону | B22: ккал/нм3 | C22: =(Таб3!K4*Таб1!C5+Таб1!C5*Таб1!C11*10^-3*C33)/4.187 -> 560.24887 | D22: =C36 -> 514.78769 | E22: =D36 -> 296.57245 | F22: =E36 -> 265.22187 | G22: =F36 -> 202.9683 | H22: =G36 -> 198.18144 | I22: =H36 -> 167.19801 | J22: =I36 -> 166.93719 | K22: =J36 -> 166.80033 | L22: =K36 -> 166.72448
A23: Количество тепла газов на входе в зону | B23: Гкал/ч | C23: =Таб3!K5*C22/1000000 -> 20.000885 | D23: =C37 -> 18.465435 | E23: =D37 -> 10.688471 | F23: =E37 -> 9.8742101 | G23: =F37 -> 7.7635376 | H23: =G37 -> 7.58044 | I23: =H37 -> 6.4521713 | J23: =I37 -> 6.4875132 | K23: =J37 -> 6.5048794 | L23: =K37 -> 6.5132584
A24: Температура технологических газов на выходе по зонам | B24: оС | C24: =Таб1!C5-Таб2!C19 -> 1170 | D24: =Таб6_Расчет_выхода_ВЭР[[#This Row],[Зона 1]]-Таб2!D19 -> 720 | E24: =Таб6_Расчет_выхода_ВЭР[[#This Row],[Зона 2]]-Таб2!E19 -> 654 | F24: =Таб6_Расчет_выхода_ВЭР[[#This Row],[Зона 3]]-Таб2!F19 -> 513 | G24: =Таб6_Расчет_выхода_ВЭР[[#This Row],[Зона 4]]-Таб2!G19 -> 502 | H24: =Таб6_Расчет_выхода_ВЭР[[#This Row],[Зона 5]]-Таб2!H19 -> 431 | I24: =Таб6_Расчет_выхода_ВЭР[[#This Row],[Зона 6]]-Таб2!I19 -> 431 | J24: =Таб6_Расчет_выхода_ВЭР[[#This Row],[Зона 7]]-Таб2!J19 -> 431 | K24: =Таб6_Расчет_выхода_ВЭР[[#This Row],[Зона 8]]-Таб2!K19 -> 431 | L24: =Таб6_Расчет_выхода_ВЭР[[#This Row],[Зона 9]]-Таб2!L19 -> 431
A25: Истинная теплоёмкость уходящих газов в соответствующем интервале температур | B25: кДж/ (кг*оС) | C25: =C26/C20 -> 1.1725206 | D25: =D26/D20 -> 1.1034589 | E25: =E26/E20 -> 1.0941849 | F25: =F26/F20 -> 1.0738103 | G25: =G26/G20 -> 1.0723093 | H25: =H26/H20 -> 1.0559497 | I25: =I26/I20 -> 1.0558388 | J25: =J26/J20 -> 1.0557839 | ... L25: =L26/L20 -> 1.0557429
B26: кДж/ (м3*оС) | C26: =C8*C27+C10*C28+C12*C29+C14*C30+C16*C31+C18*C32 -> 1.813904 | D26: =D8*D27+D10*D28+D12*D29+D14*D30+D16*D31+D18*D32 -> 1.705714 | E26: =E8*E27+E10*E28+E12*E29+E14*E30+E16*E31+E18*E32 -> 1.6823449 | F26: =F8*F27+F10*F28+F12*F29+F14*F30+F16*F31+F18*F32 -> 1.6438588 | G26: =G8*G27+G10*G28+G12*G29+G14*G30+G16*G31+G18*G32 -> 1.6415609 | H26: =H8*H27+H10*H28+H12*H29+H14*H30+H16*H31+H18*H32 -> 1.6142524 | I26: =I8*I27+I10*I28+I12*I29+I14*I30+I16*I31+I18*I32 -> 1.6123003 | J26: =J8*J27+J10*J28+J12*J29+J14*J30+J16*J31+J18*J32 -> 1.6113344 | ... L26: =L8*L27+L10*L28+L12*L29+L14*L30+L16*L31+L18*L32 -> 1.6106144
A27: SO2 | B27: -//- | C27: {=IFERROR(INDEX(Пр6_Теплоёмкость_различных_газов[SO2, кДж/(м3*оС)],MATCH(MIN(IF(Пр6_Теплоёмкость_различных_газов[Температура, 0С]>=C$24,Пр6_Теплоёмкость_различных_газов[Температура, 0С],"")),Пр6_Теплоёмкость_различных_газов[Температура, 0С],0),0),"Ошибка")} -> 2.2935 | D27: {=IFERROR(INDEX(Пр6_Теплоёмкость_различных_газов[SO2, кДж/(м3*оС)],MATCH(MIN(IF(Пр6_Теплоёмкость_различных_газов[Температура, 0С]>=D$24,Пр6_Теплоёмкость_различных_газов[Температура, 0С],"")),Пр6_Теплоёмкость_различных_газов[Температура, 0С],0),0),"Ошибка")} -> 2.146 | E27: {=IFERROR(INDEX(Пр6_Теплоёмкость_различных_газов[SO2, кДж/(м3*оС)],MATCH(MIN(IF(Пр6_Теплоёмкость_различных_газов[Температура, 0С]>=E$24,Пр6_Теплоёмкость_различных_газов[Температура, 0С],"")),Пр6_Теплоёмкость_различных_газов[Температура, 0С],0),0),"Ошибка")} -> 2.132 | F27: {=IFERROR(INDEX(Пр6_Теплоёмкость_различных_газов[SO2, кДж/(м3*оС)],MATCH(MIN(IF(Пр6_Теплоёмкость_различных_газов[Температура, 0С]>=F$24,Пр6_Теплоёмкость_различных_газов[Температура, 0С],"")),Пр6_Теплоёмкость_различных_газов[Температура, 0С],0),0),"Ошибка")} -> 2.104 | G27: {=IFERROR(INDEX(Пр6_Теплоёмкость_различных_газов[SO2, кДж/(м3*оС)],MATCH(MIN(IF(Пр6_Теплоёмкость_различных_газов[Температура, 0С]>=G$24,Пр6_Теплоёмкость_различных_газов[Температура, 0С],"")),Пр6_Теплоёмкость_различных_газов[Температура, 0С],0),0),"Ошибка")} -> 2.102 | H27: {=IFERROR(INDEX(Пр6_Теплоёмкость_различных_газов[SO2, кДж/(м3*оС)],MATCH(MIN(IF(Пр6_Теплоёмкость_различных_газов[Температура, 0С]>=H$24,Пр6_Теплоёмкость_различных_газов[Температура, 0С],"")),Пр6_Теплоёмкость_различных_газов[Температура, 0С],0),0),"Ошибка")} -> 2.04 | I27: {=IFERROR(INDEX(Пр6_Теплоёмкость_различных_газов[SO2, кДж/(м3*оС)],MATCH(MIN(IF(Пр6_Теплоёмкость_различных_газов[Температура, 0С]>=I$24,Пр6_Теплоёмкость_различных_газов[Температура, 0С],"")),Пр6_Теплоёмкость_различных_газов[Температура, 0С],0),0),"Ошибка")} -> 2.04 | J27: {=IFERROR(INDEX(Пр6_Теплоёмкость_различных_газов[SO2, кДж/(м3*оС)],MATCH(MIN(IF(Пр6_Теплоёмкость_различных_газов[Температура, 0С]>=J$24,Пр6_Теплоёмкость_различных_газов[Температура, 0С],"")),Пр6_Теплоёмкость_различных_газов[Температура, 0С],0),0),"Ошибка")} -> 2.04 | ... L27: {=IFERROR(INDEX(Пр6_Теплоёмкость_различных_газов[SO2, кДж/(м3*оС)],MATCH(MIN(IF(Пр6_Теплоёмкость_различных_газов[Температура, 0С]>=L$24,Пр6_Теплоёмкость_различных_газов[Температура, 0С],"")),Пр6_Теплоёмкость_различных_газов[Температура, 0С],0),0),"Ошибка")} -> 2.04
A28: SO3 | B28: -//- | C28: =C27 -> 2.2935 | D28: =D27 -> 2.146 | E28: =E27 -> 2.132 | F28: =F27 -> 2.104 | G28: =G27 -> 2.102 | H28: =H27 -> 2.04 | I28: =I27 -> 2.04 | J28: =J27 -> 2.04 | ... L28: =L27 -> 2.04
A29: H2O | B29: -//- | C29: {=IFERROR(INDEX(Пр6_Теплоёмкость_различных_газов[H2O, кДж/(м3*оС)],MATCH(MIN(IF(Пр6_Теплоёмкость_различных_газов[Температура, 0С]>=C$24,Пр6_Теплоёмкость_различных_газов[Температура, 0С],"")),Пр6_Теплоёмкость_различных_газов[Температура, 0С],0),0),"Ошибка")} -> 1.754 | D29: {=IFERROR(INDEX(Пр6_Теплоёмкость_различных_газов[H2O, кДж/(м3*оС)],MATCH(MIN(IF(Пр6_Теплоёмкость_различных_газов[Температура, 0С]>=D$24,Пр6_Теплоёмкость_различных_газов[Температура, 0С],"")),Пр6_Теплоёмкость_различных_газов[Температура, 0С],0),0),"Ошибка")} -> 1.636 | E29: {=IFERROR(INDEX(Пр6_Теплоёмкость_различных_газов[H2O, кДж/(м3*оС)],MATCH(MIN(IF(Пр6_Теплоёмкость_различных_газов[Температура, 0С]>=E$24,Пр6_Теплоёмкость_различных_газов[Температура, 0С],"")),Пр6_Теплоёмкость_различных_газов[Температура, 0С],0),0),"Ошибка")} -> 1.622 | F29: {=IFERROR(INDEX(Пр6_Теплоёмкость_различных_газов[H2O, кДж/(м3*оС)],MATCH(MIN(IF(Пр6_Теплоёмкость_различных_газов[Температура, 0С]>=F$24,Пр6_Теплоёмкость_различных_газов[Температура, 0С],"")),Пр6_Теплоёмкость_различных_газов[Температура, 0С],0),0),"Ошибка")} -> 1.586 | G29: {=IFERROR(INDEX(Пр6_Теплоёмкость_различных_газов[H2O, кДж/(м3*оС)],MATCH(MIN(IF(Пр6_Теплоёмкость_различных_газов[Температура, 0С]>=G$24,Пр6_Теплоёмкость_различных_газов[Температура, 0С],"")),Пр6_Теплоёмкость_различных_газов[Температура, 0С],0),0),"Ошибка")} -> 1.583 | H29: {=IFERROR(INDEX(Пр6_Теплоёмкость_различных_газов[H2O, кДж/(м3*оС)],MATCH(MIN(IF(Пр6_Теплоёмкость_различных_газов[Температура, 0С]>=H$24,Пр6_Теплоёмкость_различных_газов[Температура, 0С],"")),Пр6_Теплоёмкость_различных_газов[Температура, 0С],0),0),"Ошибка")} -> 1.568 | I29: {=IFERROR(INDEX(Пр6_Теплоёмкость_различных_газов[H2O, кДж/(м3*оС)],MATCH(MIN(IF(Пр6_Теплоёмкость_различных_газов[Температура, 0С]>=I$24,Пр6_Теплоёмкость_различных_газов[Температура, 0С],"")),Пр6_Теплоёмкость_различных_газов[Температура, 0С],0),0),"Ошибка")} -> 1.568 | J29: {=IFERROR(INDEX(Пр6_Теплоёмкость_различных_газов[H2O, кДж/(м3*оС)],MATCH(MIN(IF(Пр6_Теплоёмкость_различных_газов[Температура, 0С]>=J$24,Пр6_Теплоёмкость_различных_газов[Температура, 0С],"")),Пр6_Теплоёмкость_различных_газов[Температура, 0С],0),0),"Ошибка")} -> 1.568 | ... L29: {=IFERROR(INDEX(Пр6_Теплоёмкость_различных_газов[H2O, кДж/(м3*оС)],MATCH(MIN(IF(Пр6_Теплоёмкость_различных_газов[Температура, 0С]>=L$24,Пр6_Теплоёмкость_различных_газов[Температура, 0С],"")),Пр6_Теплоёмкость_различных_газов[Температура, 0С],0),0),"Ошибка")} -> 1.568
A30: O2 | B30: -//- | C30: {=IFERROR(INDEX(Пр6_Теплоёмкость_различных_газов[О2, кДж/(м3*оС)],MATCH(MIN(IF(Пр6_Теплоёмкость_различных_газов[Температура, 0С]>=C$24,Пр6_Теплоёмкость_различных_газов[Температура, 0С],"")),Пр6_Теплоёмкость_различных_газов[Температура, 0С],0),0),"Ошибка")} -> 1.467 | D30: {=IFERROR(INDEX(Пр6_Теплоёмкость_различных_газов[О2, кДж/(м3*оС)],MATCH(MIN(IF(Пр6_Теплоёмкость_различных_газов[Температура, 0С]>=D$24,Пр6_Теплоёмкость_различных_газов[Температура, 0С],"")),Пр6_Теплоёмкость_различных_газов[Температура, 0С],0),0),"Ошибка")} -> 1.422 | E30: {=IFERROR(INDEX(Пр6_Теплоёмкость_различных_газов[О2, кДж/(м3*оС)],MATCH(MIN(IF(Пр6_Теплоёмкость_различных_газов[Температура, 0С]>=E$24,Пр6_Теплоёмкость_различных_газов[Температура, 0С],"")),Пр6_Теплоёмкость_различных_газов[Температура, 0С],0),0),"Ошибка")} -> 1.416 | F30: {=IFERROR(INDEX(Пр6_Теплоёмкость_различных_газов[О2, кДж/(м3*оС)],MATCH(MIN(IF(Пр6_Теплоёмкость_различных_газов[Температура, 0С]>=F$24,Пр6_Теплоёмкость_различных_газов[Температура, 0С],"")),Пр6_Теплоёмкость_различных_газов[Температура, 0С],0),0),"Ошибка")} -> 1.394 | G30: {=IFERROR(INDEX(Пр6_Теплоёмкость_различных_газов[О2, кДж/(м3*оС)],MATCH(MIN(IF(Пр6_Теплоёмкость_различных_газов[Температура, 0С]>=G$24,Пр6_Теплоёмкость_различных_газов[Температура, 0С],"")),Пр6_Теплоёмкость_различных_газов[Температура, 0С],0),0),"Ошибка")} -> 1.392 | H30: {=IFERROR(INDEX(Пр6_Теплоёмкость_различных_газов[О2, кДж/(м3*оС)],MATCH(MIN(IF(Пр6_Теплоёмкость_различных_газов[Температура, 0С]>=H$24,Пр6_Теплоёмкость_различных_газов[Температура, 0С],"")),Пр6_Теплоёмкость_различных_газов[Температура, 0С],0),0),"Ошибка")} -> 1.378 | I30: {=IFERROR(INDEX(Пр6_Теплоёмкость_различных_газов[О2, кДж/(м3*оС)],MATCH(MIN(IF(Пр6_Теплоёмкость_различных_газов[Температура, 0С]>=I$24,Пр6_Теплоёмкость_различных_газов[Температура, 0С],"")),Пр6_Теплоёмкость_различных_газов[Температура, 0С],0),0),"Ошибка")} -> 1.378 | J30: {=IFERROR(INDEX(Пр6_Теплоёмкость_различных_газов[О2, кДж/(м3*оС)],MATCH(MIN(IF(Пр6_Теплоёмкость_различных_газов[Температура, 0С]>=J$24,Пр6_Теплоёмкость_различных_газов[Температура, 0С],"")),Пр6_Теплоёмкость_различных_газов[Температура, 0С],0),0),"Ошибка")} -> 1.378 | ... L30: {=IFERROR(INDEX(Пр6_Теплоёмкость_различных_газов[О2, кДж/(м3*оС)],MATCH(MIN(IF(Пр6_Теплоёмкость_различных_газов[Температура, 0С]>=L$24,Пр6_Теплоёмкость_различных_газов[Температура, 0С],"")),Пр6_Теплоёмкость_различных_газов[Температура, 0С],0),0),"Ошибка")} -> 1.378
A31: N2 | B31: -//- | C31: {=IFERROR(INDEX(Пр6_Теплоёмкость_различных_газов[N2, кДж/(м3*оС)],MATCH(MIN(IF(Пр6_Теплоёмкость_различных_газов[Температура, 0С]>=C$24,Пр6_Теплоёмкость_различных_газов[Температура, 0С],"")),Пр6_Теплоёмкость_различных_газов[Температура, 0С],0),0),"Ошибка")} -> 1.407 | D31: {=IFERROR(INDEX(Пр6_Теплоёмкость_различных_газов[N2, кДж/(м3*оС)],MATCH(MIN(IF(Пр6_Теплоёмкость_различных_газов[Температура, 0С]>=D$24,Пр6_Теплоёмкость_различных_газов[Температура, 0С],"")),Пр6_Теплоёмкость_различных_газов[Температура, 0С],0),0),"Ошибка")} -> 1.352 | E31: {=IFERROR(INDEX(Пр6_Теплоёмкость_различных_газов[N2, кДж/(м3*оС)],MATCH(MIN(IF(Пр6_Теплоёмкость_различных_газов[Температура, 0С]>=E$24,Пр6_Теплоёмкость_различных_газов[Температура, 0С],"")),Пр6_Теплоёмкость_различных_газов[Температура, 0С],0),0),"Ошибка")} -> 1.346 | F31: {=IFERROR(INDEX(Пр6_Теплоёмкость_различных_газов[N2, кДж/(м3*оС)],MATCH(MIN(IF(Пр6_Теплоёмкость_различных_газов[Температура, 0С]>=F$24,Пр6_Теплоёмкость_различных_газов[Температура, 0С],"")),Пр6_Теплоёмкость_различных_газов[Температура, 0С],0),0),"Ошибка")} -> 1.332 | G31: {=IFERROR(INDEX(Пр6_Теплоёмкость_различных_газов[N2, кДж/(м3*оС)],MATCH(MIN(IF(Пр6_Теплоёмкость_различных_газов[Температура, 0С]>=G$24,Пр6_Теплоёмкость_различных_газов[Температура, 0С],"")),Пр6_Теплоёмкость_различных_газов[Температура, 0С],0),0),"Ошибка")} -> 1.331 | H31: {=IFERROR(INDEX(Пр6_Теплоёмкость_различных_газов[N2, кДж/(м3*оС)],MATCH(MIN(IF(Пр6_Теплоёмкость_различных_газов[Температура, 0С]>=H$24,Пр6_Теплоёмкость_различных_газов[Температура, 0С],"")),Пр6_Теплоёмкость_различных_газов[Температура, 0С],0),0),"Ошибка")} -> 1.324 | I31: {=IFERROR(INDEX(Пр6_Теплоёмкость_различных_газов[N2, кДж/(м3*оС)],MATCH(MIN(IF(Пр6_Теплоёмкость_различных_газов[Температура, 0С]>=I$24,Пр6_Теплоёмкость_различных_газов[Температура, 0С],"")),Пр6_Теплоёмкость_различных_газов[Температура, 0С],0),0),"Ошибка")} -> 1.324 | J31: {=IFERROR(INDEX(Пр6_Теплоёмкость_различных_газов[N2, кДж/(м3*оС)],MATCH(MIN(IF(Пр6_Теплоёмкость_различных_газов[Температура, 0С]>=J$24,Пр6_Теплоёмкость_различных_газов[Температура, 0С],"")),Пр6_Теплоёмкость_различных_газов[Температура, 0С],0),0),"Ошибка")} -> 1.324 | ... L31: {=IFERROR(INDEX(Пр6_Теплоёмкость_различных_газов[N2, кДж/(м3*оС)],MATCH(MIN(IF(Пр6_Теплоёмкость_различных_газов[Температура, 0С]>=L$24,Пр6_Теплоёмкость_различных_газов[Температура, 0С],"")),Пр6_Теплоёмкость_различных_газов[Температура, 0С],0),0),"Ошибка")} -> 1.324
